Workbook
Name HOLANDA: #REF!

Sheet Ordenes
A1: Distribuidora | B1: Categoria | C1: Linea | D1: Modelo | E1: N° de activo | F1: Serie | G1: No. puertas | H1: Imagen | I1: Canal | J1: Hora de atención | K1: Observaciones | L1: Tipo de Servicio | M1: Id de Servicio | N1: Tipo de Actividad | O1: Actividad | P1: Dato de prospección | Q1: Tipo de orden | R1: N° de Cliente | S1: Nombre punto de venta | T1: Calle | U1: Número | V1: Entre calle | W1: y calle | X1: Colonia | Y1: Municipio | Z1: Código Postal | AA1: Telefono y/o fax | AB1: Nombre contacto punto de venta | AC1: Correo electrónico del contacto | AD1: Latitud | AE1: Longitud | AF1: Distribuidora o Puesto de trabajo | AG1: Código Postal Generado | AH1: Colonia Generado | AI1: Ciudad Generado | AJ1: Estado Generado | AK1: Pais Generado | AL1: ServiceIdSelector | AM1: ServiceTypeIdSelector | AN1: ModelNameSelector | MY1: MOVEMENT
AL2: =IF(IFERROR(MATCH(CONCATENATE($L2, "-",$B2),ServIdsByServTypes!$A$1:$ZZ$1,0), -1)<1,IF(IFERROR(MATCH($L2,ServIdsByServTypes!$A$1:$ZZ$1,0), -1)<1, 100,MATCH($L2,ServIdsByServTypes!$A$1:$ZZ$1,0)), MATCH(CONCATENATE($L2, "-",$B2),ServIdsByServTypes!$A$1:$ZZ$1,0)) -> 100 | AM2: =IF(IFERROR(MATCH($B2,ServIdsByServTypes!$A$1:$ZZ$1,0),-1)<1,100, MATCH($B2,ServIdsByServTypes!$A$1:$ZZ$1,0)) -> 100 | AN2: =IF(IFERROR(MATCH(CONCATENATE($B2, "-",$C2),ModelsByLines!$A$1:$ZZ$1,0), -1)<1,IF(IFERROR(MATCH($C2,ModelsByLines!$A$1:$ZZ$1,0), -1)<1, 100,MATCH($C2,ModelsByLines!$A$1:$ZZ$1,0)), MATCH(CONCATENATE($B2, "-",$C2),ModelsByLines!$A$1:$ZZ$1,0)) -> 100
AL3: =IF(IFERROR(MATCH(CONCATENATE($L3, "-",$B3),ServIdsByServTypes!$A$1:$ZZ$1,0), -1)<1,IF(IFERROR(MATCH($L3,ServIdsByServTypes!$A$1:$ZZ$1,0), -1)<1, 100,MATCH($L3,ServIdsByServTypes!$A$1:$ZZ$1,0)), MATCH(CONCATENATE($L3, "-",$B3),ServIdsByServTypes!$A$1:$ZZ$1,0)) -> 100 | AM3: =IF(IFERROR(MATCH($B3,ServIdsByServTypes!$A$1:$ZZ$1,0),-1)<1,100, MATCH($B3,ServIdsByServTypes!$A$1:$ZZ$1,0)) -> 100 | AN3: =IF(IFERROR(MATCH(CONCATENATE($B3, "-",$C3),ModelsByLines!$A$1:$ZZ$1,0), -1)<1,IF(IFERROR(MATCH($C3,ModelsByLines!$A$1:$ZZ$1,0), -1)<1, 100,MATCH($C3,ModelsByLines!$A$1:$ZZ$1,0)), MATCH(CONCATENATE($B3, "-",$C3),ModelsByLines!$A$1:$ZZ$1,0)) -> 100
AL4: =IF(IFERROR(MATCH(CONCATENATE($L4, "-",$B4),ServIdsByServTypes!$A$1:$ZZ$1,0), -1)<1,IF(IFERROR(MATCH($L4,ServIdsByServTypes!$A$1:$ZZ$1,0), -1)<1, 100,MATCH($L4,ServIdsByServTypes!$A$1:$ZZ$1,0)), MATCH(CONCATENATE($L4, "-",$B4),ServIdsByServTypes!$A$1:$ZZ$1,0)) -> 100 | AM4: =IF(IFERROR(MATCH($B4,ServIdsByServTypes!$A$1:$ZZ$1,0),-1)<1,100, MATCH($B4,ServIdsByServTypes!$A$1:$ZZ$1,0)) -> 100 | AN4: =IF(IFERROR(MATCH(CONCATENATE($B4, "-",$C4),ModelsByLines!$A$1:$ZZ$1,0), -1)<1,IF(IFERROR(MATCH($C4,ModelsByLines!$A$1:$ZZ$1,0), -1)<1, 100,MATCH($C4,ModelsByLines!$A$1:$ZZ$1,0)), MATCH(CONCATENATE($B4, "-",$C4),ModelsByLines!$A$1:$ZZ$1,0)) -> 100
AL5: =IF(IFERROR(MATCH(CONCATENATE($L5, "-",$B5),ServIdsByServTypes!$A$1:$ZZ$1,0), -1)<1,IF(IFERROR(MATCH($L5,ServIdsByServTypes!$A$1:$ZZ$1,0), -1)<1, 100,MATCH($L5,ServIdsByServTypes!$A$1:$ZZ$1,0)), MATCH(CONCATENATE($L5, "-",$B5),ServIdsByServTypes!$A$1:$ZZ$1,0)) -> 100 | AM5: =IF(IFERROR(MATCH($B5,ServIdsByServTypes!$A$1:$ZZ$1,0),-1)<1,100, MATCH($B5,ServIdsByServTypes!$A$1:$ZZ$1,0)) -> 100 | AN5: =IF(IFERROR(MATCH(CONCATENATE($B5, "-",$C5),ModelsByLines!$A$1:$ZZ$1,0), -1)<1,IF(IFERROR(MATCH($C5,ModelsByLines!$A$1:$ZZ$1,0), -1)<1, 100,MATCH($C5,ModelsByLines!$A$1:$ZZ$1,0)), MATCH(CONCATENATE($B5, "-",$C5),ModelsByLines!$A$1:$ZZ$1,0)) -> 100
AL6: =IF(IFERROR(MATCH(CONCATENATE($L6, "-",$B6),ServIdsByServTypes!$A$1:$ZZ$1,0), -1)<1,IF(IFERROR(MATCH($L6,ServIdsByServTypes!$A$1:$ZZ$1,0), -1)<1, 100,MATCH($L6,ServIdsByServTypes!$A$1:$ZZ$1,0)), MATCH(CONCATENATE($L6, "-",$B6),ServIdsByServTypes!$A$1:$ZZ$1,0)) -> 100 | AM6: =IF(IFERROR(MATCH($B6,ServIdsByServTypes!$A$1:$ZZ$1,0),-1)<1,100, MATCH($B6,ServIdsByServTypes!$A$1:$ZZ$1,0)) -> 100 | AN6: =IF(IFERROR(MATCH(CONCATENATE($B6, "-",$C6),ModelsByLines!$A$1:$ZZ$1,0), -1)<1,IF(IFERROR(MATCH($C6,ModelsByLines!$A$1:$ZZ$1,0), -1)<1, 100,MATCH($C6,ModelsByLines!$A$1:$ZZ$1,0)), MATCH(CONCATENATE($B6, "-",$C6),ModelsByLines!$A$1:$ZZ$1,0)) -> 100
AL7: =IF(IFERROR(MATCH(CONCATENATE($L7, "-",$B7),ServIdsByServTypes!$A$1:$ZZ$1,0), -1)<1,IF(IFERROR(MATCH($L7,ServIdsByServTypes!$A$1:$ZZ$1,0), -1)<1, 100,MATCH($L7,ServIdsByServTypes!$A$1:$ZZ$1,0)), MATCH(CONCATENATE($L7, "-",$B7),ServIdsByServTypes!$A$1:$ZZ$1,0)) -> 100 | AM7: =IF(IFERROR(MATCH($B7,ServIdsByServTypes!$A$1:$ZZ$1,0),-1)<1,100, MATCH($B7,ServIdsByServTypes!$A$1:$ZZ$1,0)) -> 100 | AN7: =IF(IFERROR(MATCH(CONCATENATE($B7, "-",$C7),ModelsByLines!$A$1:$ZZ$1,0), -1)<1,IF(IFERROR(MATCH($C7,ModelsByLines!$A$1:$ZZ$1,0), -1)<1, 100,MATCH($C7,ModelsByLines!$A$1:$ZZ$1,0)), MATCH(CONCATENATE($B7, "-",$C7),ModelsByLines!$A$1:$ZZ$1,0)) -> 100
AL8: =IF(IFERROR(MATCH(CONCATENATE($L8, "-",$B8),ServIdsByServTypes!$A$1:$ZZ$1,0), -1)<1,IF(IFERROR(MATCH($L8,ServIdsByServTypes!$A$1:$ZZ$1,0), -1)<1, 100,MATCH($L8,ServIdsByServTypes!$A$1:$ZZ$1,0)), MATCH(CONCATENATE($L8, "-",$B8),ServIdsByServTypes!$A$1:$ZZ$1,0)) -> 100 | AM8: =IF(IFERROR(MATCH($B8,ServIdsByServTypes!$A$1:$ZZ$1,0),-1)<1,100, MATCH($B8,ServIdsByServTypes!$A$1:$ZZ$1,0)) -> 100 | AN8: =IF(IFERROR(MATCH(CONCATENATE($B8, "-",$C8),ModelsByLines!$A$1:$ZZ$1,0), -1)<1,IF(IFERROR(MATCH($C8,ModelsByLines!$A$1:$ZZ$1,0), -1)<1, 100,MATCH($C8,ModelsByLines!$A$1:$ZZ$1,0)), MATCH(CONCATENATE($B8, "-",$C8),ModelsByLines!$A$1:$ZZ$1,0)) -> 100
AL9: =IF(IFERROR(MATCH(CONCATENATE($L9, "-",$B9),ServIdsByServTypes!$A$1:$ZZ$1,0), -1)<1,IF(IFERROR(MATCH($L9,ServIdsByServTypes!$A$1:$ZZ$1,0), -1)<1, 100,MATCH($L9,ServIdsByServTypes!$A$1:$ZZ$1,0)), MATCH(CONCATENATE($L9, "-",$B9),ServIdsByServTypes!$A$1:$ZZ$1,0)) -> 100 | AM9: =IF(IFERROR(MATCH($B9,ServIdsByServTypes!$A$1:$ZZ$1,0),-1)<1,100, MATCH($B9,ServIdsByServTypes!$A$1:$ZZ$1,0)) -> 100 | AN9: =IF(IFERROR(MATCH(CONCATENATE($B9, "-",$C9),ModelsByLines!$A$1:$ZZ$1,0), -1)<1,IF(IFERROR(MATCH($C9,ModelsByLines!$A$1:$ZZ$1,0), -1)<1, 100,MATCH($C9,ModelsByLines!$A$1:$ZZ$1,0)), MATCH(CONCATENATE($B9, "-",$C9),ModelsByLines!$A$1:$ZZ$1,0)) -> 100
AL10: =IF(IFERROR(MATCH(CONCATENATE($L10, "-",$B10),ServIdsByServTypes!$A$1:$ZZ$1,0), -1)<1,IF(IFERROR(MATCH($L10,ServIdsByServTypes!$A$1:$ZZ$1,0), -1)<1, 100,MATCH($L10,ServIdsByServTypes!$A$1:$ZZ$1,0)), MATCH(CONCATENATE($L10, "-",$B10),ServIdsByServTypes!$A$1:$ZZ$1,0)) -> 100 | AM10: =IF(IFERROR(MATCH($B10,ServIdsByServTypes!$A$1:$ZZ$1,0),-1)<1,100, MATCH($B10,ServIdsByServTypes!$A$1:$ZZ$1,0)) -> 100 | AN10: =IF(IFERROR(MATCH(CONCATENATE($B10, "-",$C10),ModelsByLines!$A$1:$ZZ$1,0), -1)<1,IF(IFERROR(MATCH($C10,ModelsByLines!$A$1:$ZZ$1,0), -1)<1, 100,MATCH($C10,ModelsByLines!$A$1:$ZZ$1,0)), MATCH(CONCATENATE($B10, "-",$C10),ModelsByLines!$A$1:$ZZ$1,0)) -> 100
AL11: =IF(IFERROR(MATCH(CONCATENATE($L11, "-",$B11),ServIdsByServTypes!$A$1:$ZZ$1,0), -1)<1,IF(IFERROR(MATCH($L11,ServIdsByServTypes!$A$1:$ZZ$1,0), -1)<1, 100,MATCH($L11,ServIdsByServTypes!$A$1:$ZZ$1,0)), MATCH(CONCATENATE($L11, "-",$B11),ServIdsByServTypes!$A$1:$ZZ$1,0)) -> 100 | AM11: =IF(IFERROR(MATCH($B11,ServIdsByServTypes!$A$1:$ZZ$1,0),-1)<1,100, MATCH($B11,ServIdsByServTypes!$A$1:$ZZ$1,0)) -> 100 | AN11: =IF(IFERROR(MATCH(CONCATENATE($B11, "-",$C11),ModelsByLines!$A$1:$ZZ$1,0), -1)<1,IF(IFERROR(MATCH($C11,ModelsByLines!$A$1:$ZZ$1,0), -1)<1, 100,MATCH($C11,ModelsByLines!$A$1:$ZZ$1,0)), MATCH(CONCATENATE($B11, "-",$C11),ModelsByLines!$A$1:$ZZ$1,0)) -> 100
AL12: =IF(IFERROR(MATCH(CONCATENATE($L12, "-",$B12),ServIdsByServTypes!$A$1:$ZZ$1,0), -1)<1,IF(IFERROR(MATCH($L12,ServIdsByServTypes!$A$1:$ZZ$1,0), -1)<1, 100,MATCH($L12,ServIdsByServTypes!$A$1:$ZZ$1,0)), MATCH(CONCATENATE($L12, "-",$B12),ServIdsByServTypes!$A$1:$ZZ$1,0)) -> 100 | AM12: =IF(IFERROR(MATCH($B12,ServIdsByServTypes!$A$1:$ZZ$1,0),-1)<1,100, MATCH($B12,ServIdsByServTypes!$A$1:$ZZ$1,0)) -> 100 | AN12: =IF(IFERROR(MATCH(CONCATENATE($B12, "-",$C12),ModelsByLines!$A$1:$ZZ$1,0), -1)<1,IF(IFERROR(MATCH($C12,ModelsByLines!$A$1:$ZZ$1,0), -1)<1, 100,MATCH($C12,ModelsByLines!$A$1:$ZZ$1,0)), MATCH(CONCATENATE($B12, "-",$C12),ModelsByLines!$A$1:$ZZ$1,0)) -> 100
AL13: =IF(IFERROR(MATCH(CONCATENATE($L13, "-",$B13),ServIdsByServTypes!$A$1:$ZZ$1,0), -1)<1,IF(IFERROR(MATCH($L13,ServIdsByServTypes!$A$1:$ZZ$1,0), -1)<1, 100,MATCH($L13,ServIdsByServTypes!$A$1:$ZZ$1,0)), MATCH(CONCATENATE($L13, "-",$B13),ServIdsByServTypes!$A$1:$ZZ$1,0)) -> 100 | AM13: =IF(IFERROR(MATCH($B13,ServIdsByServTypes!$A$1:$ZZ$1,0),-1)<1,100, MATCH($B13,ServIdsByServTypes!$A$1:$ZZ$1,0)) -> 100 | AN13: =IF(IFERROR(MATCH(CONCATENATE($B13, "-",$C13),ModelsByLines!$A$1:$ZZ$1,0), -1)<1,IF(IFERROR(MATCH($C13,ModelsByLines!$A$1:$ZZ$1,0), -1)<1, 100,MATCH($C13,ModelsByLines!$A$1:$ZZ$1,0)), MATCH(CONCATENATE($B13, "-",$C13),ModelsByLines!$A$1:$ZZ$1,0)) -> 100
... AL500: =IF(IFERROR(MATCH(CONCATENATE($L500, "-",$B500),ServIdsByServTypes!$A$1:$ZZ$1,0), -1)<1,IF(IFERROR(MATCH($L500,ServIdsByServTypes!$A$1:$ZZ$1,0), -1)<1, 100,MATCH($L500,ServIdsByServTypes!$A$1:$ZZ$1,0)), MATCH(CONCATENATE($L500, "-",$B500),ServIdsByServTypes!$A$1:$ZZ$1,0)) -> 100 | AM500: =IF(IFERROR(MATCH($B500,ServIdsByServTypes!$A$1:$ZZ$1,0),-1)<1,100, MATCH($B500,ServIdsByServTypes!$A$1:$ZZ$1,0)) -> 100 | AN500: =IF(IFERROR(MATCH(CONCATENATE($B500, "-",$C500),ModelsByLines!$A$1:$ZZ$1,0), -1)<1,IF(IFERROR(MATCH($C500,ModelsByLines!$A$1:$ZZ$1,0), -1)<1, 100,MATCH($C500,ModelsByLines!$A$1:$ZZ$1,0)), MATCH(CONCATENATE($B500, "-",$C500),ModelsByLines!$A$1:$ZZ$1,0)) -> 100

Sheet CommercialChannels
A1: ID | B1: Descripción
A2: DSD | B2: Distribución Directa | C2: DSD | Distribución Directa
A3: TDC | B3: Tiendas de Conveniencia | C3: TDC | Tiendas de Conveniencia
A4: OPT | B4: On Premise Premium | C4: OPT | On Premise Premium
A5: TDP | B5: Socios Comerciales | C5: TDP | Socios Comerciales
A6: MT | B6: Auto Servicio | C6: MT | Auto Servicio
A7: RB | B7: Red Bull | C7: RB | Red Bull
A8: SC | B8: Sin Canal | C8: SC | Sin Canal

Sheet LinesByCategories
A1: 16 | CONGELADOR | B1: 12 | ENFRIADOR | C1: 14 | MAQVENDING | D1: 17 | CORTINA DE AIRE | E1: 13 | BARRIL | F1: 11 | MAQHIELO | G1: 15 | VITRINA | H1: 18 | DISPAGUA | I1: 0B | UNID REFRI VENDING | J1: 20 | CAFETERAS | K1: 1A | MESA FRIA | L1: 1E | AREASGRALES | M1: 1F | COMIDARAP | N1: 1G | ELECTBAJATEN | O1: 1H | REFRIYCONSERV | P1: 1I | SIM | Q1: 1B | MOBILIARIO | R1: 1C | CUARTOFRIO
A2: OTROS | B2: OTROS | C2: OTROS | D2: OTROS | E2: OTROS | F2: OTROS | G2: OTROS | H2: OTROS | I2: OTROS | J2: OTROS | K2: OTROS | L2: SIM | M2: SIM | N2: SIM | O2: SIM | P2: SIM | Q2: OTROS | R2: OTROS
A3: CH | B3: BVC | D3: EHF | F3: OTR
A4: EHF | B4: CCH | D4: EVF
A5: EVF | B5: CCV | D5: VF
A6: HF | B6: CFX | D6: CH
A7: VC | B7: FV
A8: VF | B8: G3
A9: otros | B9: GDM
B10: LV
B11: VR
B12: VV

Sheet ModelsByLines
A1: OTROS | B1: BVC | C1: CCH | D1: CCV | E1: CFX | F1: CH | G1: EHF | H1: EVF | I1: FV | J1: G3 | K1: GDM | L1: HF | M1: LV | N1: VC | O1: VF | P1: VR | Q1: VV | R1: SIM | S1: otros | T1: OTR | U1: 13 | BARRIL-OTROS | V1: 20 | CAFETERAS-OTROS | W1: 16 | CONGELADOR-OTROS | X1: 17 | CORTINA DE AIRE-OTROS | Y1: 18 | DISPAGUA-OTROS | Z1: 12 | ENFRIADOR-OTROS | AA1: 11 | MAQHIELO-OTROS | AB1: 14 | MAQVENDING-OTROS | AC1: 0B | UNID REFRI VENDING-OTROS | AD1: 15 | VITRINA-OTROS | AE1: 1A | MESA FRIA-OTROS | AF1: 1B | MOBILIARIO-OTROS | AG1: 1C | CUARTOFRIO-OTROS | AH1: 12 | ENFRIADOR-BVC | AI1: 12 | ENFRIADOR-CCH | AJ1: 12 | ENFRIADOR-CCV | AK1: 12 | ENFRIADOR-CFX | AL1: 16 | CONGELADOR-CH | AM1: 16 | CONGELADOR-EHF | AN1: 16 | CONGELADOR-EVF | AO1: 12 | ENFRIADOR-FV | AP1: 12 | ENFRIADOR-G3 | AQ1: 12 | ENFRIADOR-GDM | AR1: 16 | CONGELADOR-HF | AS1: 12 | ENFRIADOR-LV | AT1: 16 | CONGELADOR-VC | AU1: 16 | CONGELADOR-VF | AV1: 12 | ENFRIADOR-VR | AW1: 12 | ENFRIADOR-VV | AX1: 1E | AREASGRALES-SIM | AY1: 1F | COMIDARAP-SIM | AZ1: 1G | ELECTBAJATEN-SIM | BA1: 1H | REFRIYCONSERV-SIM | BB1: 1I | SIM-SIM | BC1: 13 | BARRIL-otros | BD1: 20 | CAFETERAS-otros | BE1: 16 | CONGELADOR-otros | BF1: 17 | CORTINA DE AIRE-otros | BG1: 18 | DISPAGUA-otros | BH1: 12 | ENFRIADOR-otros | BI1: 11 | MAQHIELO-otros | BJ1: 14 | MAQVENDING-otros | BK1: 0B | UNID REFRI VENDING-otros | BL1: 15 | VITRINA-otros | BM1: 1A | MESA FRIA-otros | BN1: 1B | MOBILIARIO-otros | BO1: 1C | CUARTOFRIO-otros | BP1: 11 | MAQHIELO-OTR
A2: 306-995 | B2: BVC01-E1 S1C115BGN | C2: CCH150 PA | D2: CCV108 PAPC | E2: CFX-05 | F2: CH170 | G2: EHF07-C2 S2C115BGN | H2: EVF08-F1P4C115BGN | I2: FV19 D BMAE R290 | J2: G313 C BMAD | K2: GDM06LD_ | L2: HFS17 C PA | M2: LV240 C BASICO | N2: VCR26-M2-REF | O2: VF1.5 C PA | P2: VR04 C PA | Q2: VV140 C NORMAL | R2: ALBAN | S2: ejemplo | T2: MAQHIE | U2: AVANT40 | V2: XXXXX | W2: 306-995 | X2: ALPHA-12 | Y2: DA001 | Z2: 360 COOLER MED BRD | AA2: B500 | AB2: 5V21 | AC2: UNID REFRI MINI | AD2: BHS200-B | AE2: MEFRI-07C | AF2: GEN MOBILIARIO | AG2: GEN CAMARA | AH2: BVC01-E1 S1C115BGN | AI2: CCH150 PA | AJ2: CCV108 PAPC | AK2: CFX-05 | AL2: CH170 | AM2: EHF07-C2 S2C115BGN | AN2: EVF08-F1P4C115BGN | AO2: FV19 D BMAE R290 | AP2: G313 C BMAD | AQ2: GDM06LD_ | AR2: HFS17 C PA | AS2: LV240 C BASICO | AT2: VCR26-M2-REF | AU2: VF1.5 C PA | AV2: VR04 C PA | AW2: VV140 C NORMAL | AX2: ALBAN | AY2: BASC | AZ2: BOMBA | BA2: CFBTC | BB2: TABLERO | BC2: AVANT40 | BD2: XXXXX | BE2: 306-995 | BF2: ALPHA-12 | BG2: DA001 | BH2: 360 COOLER MED BRD | BI2: B500 | BJ2: 5V21 | BK2: UNID REFRI MINI | BL2: BHS200-B | BM2: MEFRI-07C | BN2: GEN MOBILIARIO | BO2: GEN CAMARA | BP2: MAQHIE
A3: 32SLC-L3-JC | B3: BVC10-B1 P2D115BGN | C3: CCH360 BMAD | D3: CCV110 PA | E3: CFX-07 | F3: CH25 | G3: EHF10-C2 S2C115BGN | H3: EVF16-F1 E4C115BGN | I3: FVC09-B1 P2D220AGE | J3: G319 C BMAD_ | K3: GDM10_ | L3: HFS25 C PA | M3: LV320_ | O3: VFD43 C BMAD R2 | P3: VR06 C BMAD UL_ | Q3: VV198 | R3: AREAGRALES | S3: CHC-110 | U3: DAVID | W3: 32SLC-L3-JC | X3: CH07 | Y3: WK5011Q | Z3: ACV400 | AA3: B900 | AB3: 6V21VEND | AC3: UNID REFRI ROYAL | AD3: DRD3-N | AE3: CSMFSI04811_ | AH3: BVC10-B1 P2D115BGN | AI3: CCH360 BMAD | AJ3: CCV110 PA | AK3: CFX-07 | AL3: CH25 | AM3: EHF10-C2 S2C115BGN | AN3: EVF16-F1 E4C115BGN | AO3: FVC09-B1 P2D220AGE | AP3: G319 C BMAD_ | AQ3: GDM10_ | AR3: HFS25 C PA | AS3: LV320_ | AU3: VFD43 C BMAD R2 | AV3: VR06 C BMAD UL_ | AW3: VV198 | AX3: AREAGRALES | AY3: CALPAN | AZ3: BOMBASU | BA3: CFBTH | BC3: DAVID | BE3: 32SLC-L3-JC | BF3: CH07 | BG3: WK5011Q | BH3: ACV400 | BI3: B900 | BJ3: 6V21VEND | BK3: UNID REFRI ROYAL | BL3: DRD3-N | BM3: CSMFSI04811_
A4: 360 COOLER MED BRD | B4: BVC11-B1 P1D115BGN | C4: CCH430 BMAD | D4: CCV1350 BMAD | E4: CFX-08 | F4: CHC-200 | G4: EHF10-F1 S1C115BSN | H4: EVF24-F1 P4C115BGN | I4: FVC09-B1P2C220AGNH | J4: G322 C BMAD_ | K4: GDM1058LD_ | L4: HF24-1F LM BLA R2 | M4: LV420 C BASICO | O4: VFS08 C BMAD R4 | P4: VR08 C BMAD_ | Q4: VV230 | R4: BASC | U4: ESFERA | W4: AT-200 | X4: TTAC48 | Y4: HSM-310LB | Z4: ARE-300 | AA4: CBH-100 | AB4: 7V21VEND | AC4: UNID REFRI VENDING | AD4: SVS11-B4 P2C115BGN | AE4: PTP11 | AH4: BVC11-B1 P1D115BGN | AI4: CCH430 BMAD | AJ4: CCV1350 BMAD | AK4: CFX-08 | AL4: CHC-200 | AM4: EHF10-F1 S1C115BSN | AN4: EVF24-F1 P4C115BGN | AO4: FVC09-B1P2C220AGNH | AP4: G322 C BMAD_ | AQ4: GDM1058LD_ | AR4: HF24-1F LM BLA R2 | AS4: LV420 C BASICO | AU4: VFS08 C BMAD R4 | AV4: VR08 C BMAD_ | AW4: VV230 | AX4: CARP | AY4: COMIDARAP | AZ4: CAPAC | BA4: CFMT | BC4: ESFERA | BE4: AT-200 | BF4: TTAC48 | BG4: HSM-310LB | BH4: ARE-300 | BI4: CBH-100 | BJ4: 7V21VEND | BK4: UNID REFRI VENDING | BL4: SVS11-B4 P2C115BGN | BM4: PTP11
A5: 5V21 | B5: BVC13-E1 P2D115BGN | C5: CCH600 BMAD | D5: CCV144 BMAD | E5: CFX-09SL | F5: CHEPE 110 | G5: EHF11-C2 S2D115BGH | I5: FVC10-E1 P2C115BGU | J5: G326 C BMAD_ | K5: GDM12_ | M5: LV520 C BASICO | O5: VFS24 C BMAD R4 | P5: VR09 C BMAE | Q5: VV236 | R5: BOMBA | U5: KALINKA | W5: BD-365 | Z5: ARE400 | AA5: EC1406-FAP | AB5: 840 C/LEXAN TRN | AD5: VHP2 | AH5: BVC13-E1 P2D115BGN | AI5: CCH600 BMAD | AJ5: CCV144 BMAD | AK5: CFX-09SL | AL5: CHEPE 110 | AM5: EHF11-C2 S2D115BGH | AO5: FVC10-E1 P2C115BGU | AP5: G326 C BMAD_ | AQ5: GDM12_ | AS5: LV520 C BASICO | AU5: VFS24 C BMAD R4 | AV5: VR09 C BMAE | AW5: VV236 | AX5: CASCN | AY5: MICRO | AZ5: CECA | BA5: CONSHIE | BC5: KALINKA | BE5: BD-365 | BH5: ARE400 | BI5: EC1406-FAP | BJ5: 840 C/LEXAN TRN | BL5: VHP2
A6: 6V21VEND | B6: BVC17B1 E2C115BGN | C6: CCH800 BMAE | D6: CCV144 BMAE | E6: CFX-10 | F6: CHGL160 | G6: EHF25-F2 S1C115BSN | I6: FVC12-E1 P2C115BGU | J6: G342 C BMAD_ | K6: GDM12RF_ | P6: VR1.5 C PA | Q6: VV310_ | R6: BOMBASU | U6: V100 | W6: BY0GP1E0U | Z6: ARV01050 | AA6: EY0404A | AB6: 8V21VEND | AD6: VIT VLH17 C BMAE | AH6: BVC17B1 E2C115BGN | AI6: CCH800 BMAE | AJ6: CCV144 BMAE | AK6: CFX-10 | AL6: CHGL160 | AM6: EHF25-F2 S1C115BSN | AO6: FVC12-E1 P2C115BGU | AP6: G342 C BMAD_ | AQ6: GDM12RF_ | AV6: VR1.5 C PA | AW6: VV310_ | AX6: CERR | AY6: OTROCR | AZ6: CONTAC | BA6: KOSKA | BC6: V100 | BE6: BY0GP1E0U | BH6: ARV01050 | BI6: EY0404A | BJ6: 8V21VEND | BL6: VIT VLH17 C BMAE
A7: 7V21VEND | B7: BVC17-B1P2D115BGNH | D7: CCV190 PA | E7: CFX-11 | F7: CHL-125PH | I7: FVC14-D1 E2C115BGN | J7: G372 C BMAD_ | K7: GDM14RF_ | P7: VR10 C BMAD | Q7: VV360 | R7: CALPAN | U7: V200 | W7: CPC25U160 | Z7: ARV400_ | AA7: FHC680M | AB7: MAQUINA VENDING | AD7: VIT VLH29 C BMAE | AH7: BVC17-B1P2D115BGNH | AJ7: CCV190 PA | AK7: CFX-11 | AL7: CHL-125PH | AO7: FVC14-D1 E2C115BGN | AP7: G372 C BMAD_ | AQ7: GDM14RF_ | AV7: VR10 C BMAD | AW7: VV360 | AX7: DRENPLU | AY7: QUES | AZ7: ELECBAJTEN | BA7: REFRIYCONS | BC7: V200 | BE7: CPC25U160 | BH7: ARV400_ | BI7: FHC680M | BJ7: MAQUINA VENDING | BL7: VIT VLH29 C BMAE
A8: 840 C/LEXAN TRN | B8: BVC19B1 E2C115BGN | D8: CCV192 BMAD R2 | E8: CFX-13 | F8: CHL-68PH | I8: FVC14-D1E2C115BGNH | J8: G342 D BMAR R2 3PC | K8: GDM15_ | P8: VR11 C BMAD_ | Q8: VV400 | R8: CAPAC | U8: V300 | W8: CPC25UN17 | Z8: ARV600 | AA8: FRAPE | AB8: ROYAL550 | AD8: VIT VLH34 C BMAE | AH8: BVC19B1 E2C115BGN | AJ8: CCV192 BMAD R2 | AK8: CFX-13 | AL8: CHL-68PH | AO8: FVC14-D1E2C115BGNH | AP8: G342 D BMAR R2 3PC | AQ8: GDM15_ | AV8: VR11 C BMAD_ | AW8: VV400 | AX8: DRENSAN | AY8: REBA | AZ8: HIDRONEUMA | BA8: SALCHKOXKA | BC8: V300 | BE8: CPC25UN17 | BH8: ARV600 | BI8: FRAPE | BJ8: ROYAL550 | BL8: VIT VLH34 C BMAE
A9: 8V21VEND | B9: BVC20B1 E2C115BPN | D9: CCV200 C BMAD | E9: CFX-14 | F9: CHP-105 | I9: FVC18-B1 P2C220AGE | J9: G316 C BMAE_ | K9: GDM26_ | P9: VR12 C BMAD | Q9: VV430 C NORMAL | R9: CARP | U9: V400_ | W9: CV 200 | Z9: BABY COOLER 2020 | AA9: IQ550 | AB9: ROYAL660 | AD9: PHS13 F2 PS1C115BS | AH9: BVC20B1 E2C115BPN | AJ9: CCV200 C BMAD | AK9: CFX-14 | AL9: CHP-105 | AO9: FVC18-B1 P2C220AGE | AP9: G316 C BMAE_ | AQ9: GDM26_ | AV9: VR12 C BMAD | AW9: VV430 C NORMAL | AX9: HIDRONEU | AY9: ROST | AZ9: ILUEXT | BA9: VITRC | BC9: V400_ | BE9: CV 200 | BH9: BABY COOLER 2020 | BI9: IQ550 | BJ9: ROYAL660 | BL9: PHS13 F2 PS1C115BS
A10: ACV400 | B10: BVC25-B1 P2D115BGN | D10: CCV24 C PA | E10: CFX-15 | F10: CHP-125 | I10: FVC19-E1P2C115BGNH | J10: G316 C BMAD | K10: GDM30LD | P10: VR13 C BMAD | Q10: VV610 C NORMAL | R10: CASCN | U10: BARRIL | W10: CV 280 | Z10: BF140 | AA10: ITV2442 | AB10: ROYAL804 | AD10: PHS17 F2 PS1C115BS | AH10: BVC25-B1 P2D115BGN | AJ10: CCV24 C PA | AK10: CFX-15 | AL10: CHP-125 | AO10: FVC19-E1P2C115BGNH | AP10: G316 C BMAD | AQ10: GDM30LD | AV10: VR13 C BMAD | AW10: VV610 C NORMAL | AX10: IMPER | AY10: TAMAL | AZ10: ILUINT | BC10: BARRIL | BE10: CV 280 | BH10: BF140 | BI10: ITV2442 | BJ10: ROYAL804 | BL10: PHS17 F2 PS1C115BS
A11: ALPHA-12 | B11: BVC42-B2 P2D115BGN | D11: CCV240 C BMAD | E11: CFX-16 | F11: CHP-125H | I11: FVC20-B4P2C115BGNH | J11: G319 D BMAD R2_ | K11: GDM33_ | P11: VR17 C BMAD_ | Q11: VVC14-E3 R2C115BGN | R11: CECA | W11: CVC04HCUM12 | Z11: BFA246 | AA11: ITV5231 | AB11: G319 C BMAD CO2_ | AD11: VCG200F2PS1C115BGN | AH11: BVC42-B2 P2D115BGN | AJ11: CCV240 C BMAD | AK11: CFX-16 | AL11: CHP-125H | AO11: FVC20-B4P2C115BGNH | AP11: G319 D BMAD R2_ | AQ11: GDM33_ | AV11: VR17 C BMAD_ | AW11: VVC14-E3 R2C115BGN | AX11: LAVABO | AZ11: INSTEL | BE11: CVC04HCUM12 | BH11: BFA246 | BI11: ITV5231 | BJ11: G319 C BMAD CO2_ | BL11: VCG200F2PS1C115BGN
A12: ARE-300 | B12: BVC63-B3 P2I115BPN | D12: CCV252 BMAE | E12: CFX-17 | F12: CHP-170 | I12: FVC20-E4 P2C115BGN | J12: G319 D BMAR R2 | K12: GDM35_ | P12: VR18 C BMAD | R12: CERR | W12: CVC-08 | Z12: BFA366AFW | AA12: ITV5340 | AD12: VFG-150R2 | AH12: BVC63-B3 P2I115BPN | AJ12: CCV252 BMAE | AK12: CFX-17 | AL12: CHP-170 | AO12: FVC20-E4 P2C115BGN | AP12: G319 D BMAR R2 | AQ12: GDM35_ | AV12: VR18 C BMAD | AX12: LINEST | AZ12: INTERR | BE12: CVC-08 | BH12: BFA366AFW | BI12: ITV5340 | BL12: VFG-150R2
A13: ARE400 | D13: CCV270 C BMAD PP | E13: CFX-19 | F13: CHP-68 | I13: FVC26-B1P2C220AGNH | J13: G3D26 D BMAR R2 | K13: GDM37_ | P13: VR19 C BMAD | R13: CFBTC | W13: CVC-15 | Z13: BHF390 D BMAE R290 | AA13: KM-1301RH | AJ13: CCV270 C BMAD PP | AK13: CFX-19 | AL13: CHP-68 | AO13: FVC26-B1P2C220AGNH | AP13: G3D26 D BMAR R2 | AQ13: GDM37_ | AV13: VR19 C BMAD | AX13: LLAV | BE13: CVC-15 | BH13: BHF390 D BMAE R290 | BI13: KM-1301RH
A14: ARV01050 | D14: CCV315 BMAE 127V | E14: CFX-19 HC | F14: CHP-83 | I14: FVC26-E1 P2C115BGU | K14: GDM41_ | P14: VR20 C BMAD | R14: CFBTH | W14: CVP-11H | Z14: BHS100-B | AA14: KM-1600MAH | AJ14: CCV315 BMAE 127V | AK14: CFX-19 HC | AL14: CHP-83 | AO14: FVC26-E1 P2C115BGU | AQ14: GDM41_ | AV14: VR20 C BMAD | AX14: LOSA | BE14: CVP-11H | BH14: BHS100-B | BI14: KM-1600MAH
A15: ARV400_ | D15: CCV320 BMAD | E15: CFX-20_1P | I15: FVC28-E1P2C127BGNH | K15: GDM43_ | P15: VR25 C BMAD | R15: CFMT | W15: CVP-15 | Z15: BHS10-F2 E1C115BSN | AA15: KM-1900SAH | AJ15: CCV320 BMAD | AK15: CFX-20_1P | AO15: FVC28-E1P2C127BGNH | AQ15: GDM43_ | AV15: VR25 C BMAD | AX15: MARQ | BE15: CVP-15 | BH15: BHS10-F2 E1C115BSN | BI15: KM-1900SAH
A16: ARV600 | D16: CCV355 BMAE | E16: CFX-24_2P | I16: FVC40-B2P2C220AGNH | K16: GDM45_ | P16: VR26 C BMAD | R16: COMIDARAP | W16: ECONIC 300 | Z16: BHS150-B | AA16: KM-500 MAF | AJ16: CCV355 BMAE | AK16: CFX-24_2P | AO16: FVC40-B2P2C220AGNH | AQ16: GDM45_ | AV16: VR26 C BMAD | AX16: MONTEN | BE16: ECONIC 300 | BH16: BHS150-B | BI16: KM-500 MAF
A17: AT-200 | D17: CCV376 BMAR R2 PP | E17: CFX-30_3P | I17: FVC53-E2 P2C115BGN | K17: GDM49_ | P17: VR27 CZ HC | R17: CONSHIE | W17: HFSL293-1I016 | Z17: BHS17-F2 E1C115BSN | AA17: KM-630 | AJ17: CCV376 BMAR R2 PP | AK17: CFX-30_3P | AO17: FVC53-E2 P2C115BGN | AQ17: GDM49_ | AV17: VR27 CZ HC | AX17: MUEB | BE17: HFSL293-1I016 | BH17: BHS17-F2 E1C115BSN | BI17: KM-630
A18: AVANT40 | D18: CCV400 BMAD R2 MF | E18: CFX-37_2P | K18: GDM52TMRL_ | P18: VR35 C BMAD | R18: CONTAC | W18: HFSL388-1I008 | Z18: BHS200-B | AA18: KM-900 | AJ18: CCV400 BMAD R2 MF | AK18: CFX-37_2P | AQ18: GDM52TMRL_ | AV18: VR35 C BMAD | AX18: PBANN | BE18: HFSL388-1I008 | BH18: BHS200-B | BI18: KM-900
A19: B500 | D19: CCV450CBMADPPST220 | E19: CFX-42_2P | K19: GDM6_ | P19: VR35 D BMAD | R19: DRENPLU | W19: MCS30U161 | Z19: BHS20-F2 E1C115BSN | AA19: KM-901MAH | AJ19: CCV450CBMADPPST220 | AK19: CFX-42_2P | AQ19: GDM6_ | AV19: VR35 D BMAD | AX19: PINTEXT | BE19: MCS30U161 | BH19: BHS20-F2 E1C115BSN | BI19: KM-901MAH
A20: B900 | D20: CCV480 BMAD CE230 | E20: CFX-44 | K20: GDM69_ | P20: VRA03 B BMAD UL | R20: DRENSAN | W20: MSC30 | Z20: BHS30-F2 E1C115BSN | AA20: KML-451MAH | AJ20: CCV480 BMAD CE230 | AK20: CFX-44 | AQ20: GDM69_ | AV20: VRA03 B BMAD UL | AX20: PINTINT | BE20: MSC30 | BH20: BHS30-F2 E1C115BSN | BI20: KML-451MAH
A21: BABY COOLER 2020 | D21: CCV500 BMAD | E21: CFX-64_3P | K21: GDM72_ | P21: VRA05 B BMAD | R21: ELECBAJTEN | W21: MSC41 | Z21: BRANDED COOLER MED | AA21: KML-631MAH | AJ21: CCV500 BMAD | AK21: CFX-64_3P | AQ21: GDM72_ | AV21: VRA05 B BMAD | AX21: PISOS | BE21: MSC41 | BH21: BRANDED COOLER MED | BI21: KML-631MAH
A22: BD-365 | D22: CCV552 BMAR R2 PP | E22: CFX-SL BM LV LE | K22: GDM9 | P22: VRA12 A BMAD UL | R22: HIDRONEU | W22: MSC52 | Z22: CAN COOLER V2 | AA22: M1301SR | AJ22: CCV552 BMAR R2 PP | AK22: CFX-SL BM LV LE | AQ22: GDM9 | AV22: VRA12 A BMAD UL | AX22: PLAF | BE22: MSC52 | BH22: CAN COOLER V2 | BI22: M1301SR
A23: BF140 | D23: CCV640CBMADCE2PC22 | P23: VRA23 B BMAD | R23: HIDRONEUMA | W23: MSC70 | Z23: CH CMF15 | AA23: MCM 15 | AJ23: CCV640CBMADCE2PC22 | AV23: VRA23 B BMAD | AX23: PTAS | BE23: MSC70 | BH23: CH CMF15 | BI23: MCM 15
A24: BFA246 | D24: CCV70 BMAE PS | P24: VRD12 D BMAD | R24: ILUEXT | W24: RIO_S_100 | Z24: CH270 BMAE R2 | AA24: MHC320M | AJ24: CCV70 BMAE PS | AV24: VRD12 D BMAD | AX24: SANIT | BE24: RIO_S_100 | BH24: CH270 BMAE R2 | BI24: MHC320M
A25: BFA366AFW | D25: CCV72 PA STD | P25: VRD14 C SMP | R25: ILUINT | W25: RIO_S_150 | Z25: CH400 BMAE R2 | AA25: ML631MA | AJ25: CCV72 PA STD | AV25: VRD14 C SMP | AX25: TARJA | BE25: RIO_S_150 | BH25: CH400 BMAE R2 | BI25: ML631MA
A26: BHF390 D BMAE R290 | D26: CCV744 BMADR2CE220 | P26: VRD18-ULH | R26: IMPER | W26: RIO_S_175 | Z26: CLFX-192 B BM LVLE | AA26: ML901MA | AJ26: CCV744 BMADR2CE220 | AV26: VRD18-ULH | AX26: TINACO | BE26: RIO_S_175 | BH26: CLFX-192 B BM LVLE | BI26: ML901MA
A27: BHS100-B | D27: CCV900 BMAD | P27: VRD20 C BMAD | R27: INSTEL | W27: RIO_S_68 | Z27: CLFX-290 2PC HC | AA27: MS1000 | AJ27: CCV900 BMAD | AV27: VRD20 C BMAD | AX27: TOLDO | BE27: RIO_S_68 | BH27: CLFX-290 2PC HC | BI27: MS1000
A28: BHS10-F2 E1C115BSN | D28: CCVD213 BMADR2ULMF | P28: VRD21 C BMAD | R28: INTERR | W28: SD180 | Z28: CLH-20 SZ V400 | AA28: MS1500 | AJ28: CCVD213 BMADR2ULMF | AV28: VRD21 C BMAD | AX28: TOPES | BE28: SD180 | BH28: CLH-20 SZ V400 | BI28: MS1500
A29: BHS150-B | D29: CCVD244 BMAE R2 | P29: VRD26 C BMAD R2 H | R29: KOSKA | W29: SD-182 | Z29: CMF-15-S HC | AA29: QD02112A | AJ29: CCVD244 BMAE R2 | AV29: VRD26 C BMAD R2 H | AX29: VIDRCAN | BE29: SD-182 | BH29: CMF-15-S HC | BI29: QD02112A
A30: BHS17-F2 E1C115BSN | D30: CCVD480 BMAE 220V | P30: VRD35 D BMAD R2 | R30: LAVABO | W30: SD260_ | Z30: CMF-18-SHC | AA30: QD0452A | AJ30: CCVD480 BMAE 220V | AV30: VRD35 D BMAD R2 | BE30: SD260_ | BH30: CMF-18-SHC | BI30: QD0452A
A31: BHS200-B | D31: CCVT1300BMADPPT220 | P31: VRD37 C BMAD UL | R31: LINEST | W31: SD-298C | Z31: CNV 100 GLASS HC | AA31: QD0602A | AJ31: CCVT1300BMADPPT220 | AV31: VRD37 C BMAD UL | BE31: SD-298C | BH31: CNV 100 GLASS HC | BI31: QD0602A
A32: BHS20-F2 E1C115BSN | D32: CCVT1350 BMAB 220V | P32: VRD41SD48H | R32: LLAV | W32: SD-45 | Z32: COOKER HOME PREM | AA32: QD0802A | AJ32: CCVT1350 BMAB 220V | AV32: VRD41SD48H | BE32: SD-45 | BH32: COOKER HOME PREM | BI32: QD0802A
A33: BHS30-F2 E1C115BSN | D33: CCV192 BMAR R2 MF | P33: VRD42-4P | R33: LOSA | W33: SKYLIGHT | Z33: COUNTER TOP GDC | AA33: QD1002A | AJ33: CCV192 BMAR R2 MF | AV33: VRD42-4P | BE33: SKYLIGHT | BH33: COUNTER TOP GDC | BI33: QD1002A
A34: BRANDED COOLER MED | P34: VRD43 C BMAD | R34: MARQ | W34: THG 6 SGI | Z34: CPV-15 | AA34: QD1992N | AV34: VRD43 C BMAD | BE34: THG 6 SGI | BH34: CPV-15 | BI34: QD1992N
A35: BY0GP1E0U | P35: VRD5AI | R35: MICRO | W35: ejemplo | Z35: CRH240 | AA35: QR0450A | AV35: VRD5AI | BE35: ejemplo | BH35: CRH240 | BI35: QR0450A
A36: CAN COOLER V2 | P36: VRP03 C PA | R36: MONTEN | W36: VMC18C-M1P2D115BSC | Z36: CRV11003P-58 | AA36: SD0602A | AV36: VRP03 C PA | BE36: VMC18C-M1P2D115BSC | BH36: CRV11003P-58 | BI36: SD0602A
A37: CBH-100 | P37: VRQ35 D BMAD R2 | R37: MUEB | W37: HF15-1F LM BLA R6 | Z37: CRV140 | AA37: SD0852A | AV37: VRQ35 D BMAD R2 | BE37: HF15-1F LM BLA R6 | BH37: CRV140 | BI37: SD0852A
A38: CH CMF15 | P38: VRS01 C PA R6 | R38: OTROCR | W38: CHC-110 | Z38: CRV220SD-14 | AA38: SD1002A | AV38: VRS01 C PA R6 | BE38: CHC-110 | BH38: CRV220SD-14 | BI38: SD1002A
A39: CH07 | P39: VRS03 CBMADR2CE220 | R39: PBANN | W39: CHC-180 | Z39: CRV270 | AA39: SD-45 | AV39: VRS03 CBMADR2CE220 | BE39: CHC-180 | BH39: CRV270 | BI39: SD-45
A40: CH270 BMAE R2 | P40: VRS05 C BMAD | R40: PINTEXT | W40: CHTC-115 | Z40: CRV320 | AA40: XAC1030 | AV40: VRS05 C BMAD | BE40: CHTC-115 | BH40: CRV320 | BI40: XAC1030
...

Sheet OrderType
A1: DIAFRIO

Sheet CustomerDistributors
A1: DistributorId | B1: DistributorName | C1: CatalogDistributor
A2: 501005 | B2: ALIMENTOS BENEFITS QUERETARO ( | C2: 501005 | ALIMENTOS BENEFITS QUERETARO (
A3: 501006 | B3: ALIMENTOS BENEFITS QUERETARO ( | C3: 501006 | ALIMENTOS BENEFITS QUERETARO (
A4: 501007 | B4: ALIMENTOS BENEFITS QUERETARO ( | C4: 501007 | ALIMENTOS BENEFITS QUERETARO (
A5: 501008 | B5: ALIMENTOS BENEFITS QUERETARO ( | C5: 501008 | ALIMENTOS BENEFITS QUERETARO (
A6: 501009 | B6: DIST. BONAFONT CUERNAVACA 7254 | C6: 501009 | DIST. BONAFONT CUERNAVACA 7254
A7: 501010 | B7: DISTRIBUIDORA DANONE CANCUN | C7: 501010 | DISTRIBUIDORA DANONE CANCUN
A8: 501015 | B8: DISTRIBUIDORA KOF ALTAMIRANO | C8: 501015 | DISTRIBUIDORA KOF ALTAMIRANO
A9: 501016 | B9: DISTRIBUIDORA KOF ARCELIA | C9: 501016 | DISTRIBUIDORA KOF ARCELIA
A10: 501018 | B10: DISTRIBUIDORA KOF SUR | C10: 501018 | DISTRIBUIDORA KOF SUR
A11: 501019 | B11: DISTRIBUIDORA KOF CHALMA | C11: 501019 | DISTRIBUIDORA KOF CHALMA
A12: 501023 | B12: DISTRIBUIDORA KOF ACAYUCAN | C12: 501023 | DISTRIBUIDORA KOF ACAYUCAN
... A3473: 503919 | B3473: DISTRIBUIDORA ALPURA PISO CHIH | C3473: 503919 | DISTRIBUIDORA ALPURA PISO CHIH

Sheet Chains
A1: Code | B1: Name | C1: Catalog
A2: Z02 | B2: KOF | C2: Z02 | KOF
A3: Z41 | B3: ARCA | C3: Z41 | ARCA
A4: Z44 | B4: BIMBO | C4: Z44 | BIMBO
A5: Z98 | B5: BONAFONT | C5: Z98 | BONAFONT
A6: Z01 | B6: HEINEKEN | C6: Z01 | HEINEKEN
A7: Z52 | B7: DANONE | C7: Z52 | DANONE
A8: Z70 | B8: OTROS No Embtdres | C8: Z70 | OTROS No Embtdres
A9: Z66 | B9: GRUPO MODELO | C9: Z66 | GRUPO MODELO
A10: Z64 | B10: LALA | C10: Z64 | LALA
A11: Z47 | B11: PEÑAFIEL | C11: Z47 | PEÑAFIEL
A12: Z78 | B12: SIGMA | C12: Z78 | SIGMA
... A222: ZCO | B222: OXXO COLOMBIA | C222: ZCO | OXXO COLOMBIA

Sheet Prospecting
A1: ProspectingId | B1: FullName | C1: ShortName
A2: CF | B2: Con Firma | C2: CF
A3: NA | B3: No Aplica | C3: N/A
A4: OK | B4: OK | C4: OK

Sheet ServIdsByServTypes
A1: 13 | BARRIL | B1: 20 | CAFETERAS | C1: 16 | CONGELADOR | D1: 17 | CORTINA DE AIRE | E1: 12 | ENFRIADOR | F1: 18 | DISPAGUA | G1: 19 | HIELERA | H1: 11 | MAQHIELO | I1: 14 | MAQVENDING | J1: 15 | VITRINA | K1: 1A | MESA FRIA | L1: ? | ? | M1: 1003 | MOVIMIENTOS | N1: 1003 | MOVIMIENTOS-13 | BARRIL | O1: 1003 | MOVIMIENTOS-20 | CAFETERAS | P1: 1003 | MOVIMIENTOS-16 | CONGELADOR | Q1: 1003 | MOVIMIENTOS-17 | CORTINA DE AIRE | R1: 1003 | MOVIMIENTOS-12 | ENFRIADOR | S1: 1003 | MOVIMIENTOS-18 | DISPAGUA | T1: 1003 | MOVIMIENTOS-11 | MAQHIELO | U1: 1003 | MOVIMIENTOS-14 | MAQVENDING | V1: 1003 | MOVIMIENTOS-15 | VITRINA | W1: 1003 | MOVIMIENTOS-1A | MESA FRIA | X1: 1004 | INST. NUEVOS | Y1: 1004 | INST. NUEVOS-16 | CONGELADOR | Z1: 1004 | INST. NUEVOS-17 | CORTINA DE AIRE | AA1: 1004 | INST. NUEVOS-12 | ENFRIADOR | AB1: 1004 | INST. NUEVOS-15 | VITRINA | AC1: 1004 | INST. NUEVOS-1A | MESA FRIA
A2: 1003 | MOVIMIENTOS | B2: 1003 | MOVIMIENTOS | C2: 1003 | MOVIMIENTOS | D2: 1003 | MOVIMIENTOS | E2: 1003 | MOVIMIENTOS | F2: 1003 | MOVIMIENTOS | H2: 1003 | MOVIMIENTOS | I2: 1003 | MOVIMIENTOS | J2: 1003 | MOVIMIENTOS | K2: 1003 | MOVIMIENTOS | L2: ? | ? | M2: 1346 | INSTALACION RB | N2: 3301 | INSTALACION | O2: 3001 | INSTALACION | P2: 3601 | INSTALACION | Q2: 3701 | INSTALACION | R2: 3201 | INSTALACION | S2: 3801 | INSTALACION | T2: 3101 | INSTALACION | U2: 3401 | INSTALACION | V2: 3501 | INSTALACION | W2: 3A01 | INSTALACION | X2: 4112 | MOVIMIENTO EN FALSO | Y2: 4601 | INSTALACION | Z2: 4701 | INSTALACION | AA2: 4201 | INSTALACION | AB2: 4501 | INSTALACION | AC2: 4A01 | INSTALACION
C3: 1004 | INST. NUEVOS | D3: 1004 | INST. NUEVOS | E3: 1004 | INST. NUEVOS | J3: 1004 | INST. NUEVOS | K3: 1004 | INST. NUEVOS | M3: 1347 | RETIRO RB | N3: 3304 | INSTALACION FORANEO | O3: 3016 | RETIRO | P3: 3613 | INSTALACION CABINET | Q3: 3716 | RETIRO | R3: 3202 | INSTALACION O RETIRO | S3: 3816 | RETIRO | T3: 3116 | RETIRO | U3: 3416 | RETIRO | V3: 3502 | INSTALACION O RETIRO | W3: 3A16 | RETIRO | X3: 4201 | INSTALACION | Y3: 4604 | VISITA IMPRODUCTIVA | Z3: 4704 | VISITA IMPRODUCTIVA | AA3: 4202 | SANITIZACION | AB3: 4504 | VISITA IMPRODUCTIVA | AC3: 4A04 | VISITA IMPRODUCTIVA
M4: 1348 | REUBICACION RB | N4: 3305 | INSTALACION BARRIL MAYOR | O4: 3021 | RETIRO SIN COSTO | P4: 3614 | INSTALACION CABINET ZONAS ESPECIALES | Q4: 3721 | RETIRO SIN COSTO | R4: 3203 | INSTALACION DE ENFRIADOR Y PRODUCTO | S4: 3821 | RETIRO SIN COSTO | T4: 3130 | TRASLADO | U4: 3421 | RETIRO SIN COSTO | V4: 3504 | INSTALACION FORANEO | W4: 3A30 | TRASLADO | X4: 4202 | SANITIZACION | Y4: 4612 | MOVIMIENTO EN FALSO | Z4: 4712 | MOVIMIENTO EN FALSO | AA4: 4204 | VISITA IMPRODUCTIVA | AB4: 4512 | MOVIMIENTO EN FALSO | AC4: 4A12 | MOVIMIENTO EN FALSO
M5: 1349 | TRASLADO RB | N5: 3306 | INSTALACION BARRIL MENOR | O5: 3030 | TRASLADO | P5: 3616 | RETIRO | Q5: 3726 | REUBICACION | R5: 3204 | INSTALACION FORANEO | S5: 3830 | TRASLADO | T5: 3131 | TRASLADO FORANEO | U5: 3426 | REUBICACION | V5: 3516 | RETIRO | W5: 3A48 | MOVIMIENTO EN FALSO | X5: 4204 | VISITA IMPRODUCTIVA | AA5: 4205 | VISITA IMPRODUCTIVA - SANITIZACION
M6: 1350 | VISITA IMPRODUCTIVA RB | N6: 3308 | INSTALACION LOCAL | O6: 3050 | VISITA IMPRODUCTIVA | P6: 3621 | RETIRO SIN COSTO | Q6: 3730 | TRASLADO | R6: 3207 | D2D INSTALACION | S6: 3848 | MOVIMIENTO EN FALSO | T6: 3132 | TRASLADO LOCAL | U6: 3430 | TRASLADO | V6: 3518 | RETIRO FORANEO | W6: 3A50 | VISITA IMPRODUCTIVA | X6: 4205 | VISITA IMPRODUCTIVA - SANITIZACION | AA6: 4206 | V. IMPRODUCTIVA CAMION KOF
M7: 1351 | MOVIMIENTO EN FALSO RB | N7: 3309 | INSTALACION O RETIRO EQUIPO ADICIONAL | P7: 3626 | REUBICACION | Q7: 3737 | CAMBIO X RETIRO | R7: 3209 | INSTALACION O RETIRO EQUIPO ADICIONAL | S7: 3850 | VISITA IMPRODUCTIVA | T7: 3148 | MOVIMIENTO EN FALSO | U7: 3436 | CAMBIO X INSTALACION | V7: 3526 | REUBICACION | X7: 4206 | V. IMPRODUCTIVA CAMION KOF | AA7: 4210 | INSTALACION CAMION KOF
M8: 3001 | INSTALACION | N8: 3310 | INSTALACION RURAL | P8: 3628 | RETIRO CABINET | Q8: 3748 | MOVIMIENTO EN FALSO | R8: 3211 | INSTALACION RACK | T8: 3150 | VISITA IMPRODUCTIVA | U8: 3437 | CAMBIO X RETIRO | V8: 3527 | REUBICACION FORANEO | X8: 4210 | INSTALACION CAMION KOF | AA8: 4211 | RETIRO SIN COSTO CAMION KOF
M9: 3016 | RETIRO | N9: 3316 | RETIRO | P9: 3629 | RETIRO CABINET ZONAS ESPECIALES | Q9: 3750 | VISITA IMPRODUCTIVA | R9: 3212 | INSTALACION CAMION KOF | U9: 3448 | MOVIMIENTO EN FALSO | V9: 3530 | TRASLADO | X9: 4211 | RETIRO SIN COSTO CAMION KOF | AA9: 4212 | MOVIMIENTO EN FALSO
M10: 3021 | RETIRO SIN COSTO | N10: 3318 | RETIRO FORANEO | P10: 3630 | TRASLADO | R10: 3216 | RETIRO | U10: 3450 | VISITA IMPRODUCTIVA | V10: 3548 | MOVIMIENTO EN FALSO | X10: 4212 | MOVIMIENTO EN FALSO | AA10: 4213 | INSTALACION POR REMODELACION CTO FRIO
M11: 3030 | TRASLADO | N11: 3319 | RETIRO LOCAL | P11: 3631 | TRASLADO FORANEO | R11: 3217 | D2D RETIRO | U11: 3476 | TRABAJO EXTRA ORDINARIO | V11: 3550 | VISITA IMPRODUCTIVA | X11: 4213 | INSTALACION POR REMODELACION CTO FRIO | AA11: 4214 | VISITA IMP POR REMODELACION CTO FRIO
M12: 3050 | VISITA IMPRODUCTIVA | N12: 3320 | RETIRO RURAL | P12: 3632 | TRASLADO LOCAL | R12: 3218 | RETIRO FORANEO | U12: 3477 | INSTALACION DOMINGOS Y DIAS FESTIVOS | V12: 3555 | VISITA IMPRODUCTIVA FORANEO | X12: 4214 | VISITA IMP POR REMODELACION CTO FRIO | AA12: 4215 | INSTALACION DOMINGOS Y DIAS FESTIVOS
M13: 3101 | INSTALACION | N13: 3330 | TRASLADO | P13: 3634 | FLETE | R13: 3221 | RETIRO SIN COSTO | U13: 3478 | RETIRO DOMINGOS Y DIAS FESTIVOS | X13: 4215 | INSTALACION DOMINGOS Y DIAS FESTIVOS | AA13: 4216 | VISIT IMPRODUCT DOMINGOS Y DIAS FESTIVO
M14: 3116 | RETIRO | N14: 3331 | TRASLADO FORANEO | P14: 3638 | DIA CAMION | R14: 3222 | RETIRO STAND DE KOF FERIA FORANEA | U14: 3479 | VISIT IMPRODUCT DOMINGOS Y DIAS FESTIVO | X14: 4216 | VISIT IMPRODUCT DOMINGOS Y DIAS FESTIVO
M15: 3130 | TRASLADO | N15: 3332 | TRASLADO LOCAL | P15: 3648 | MOVIMIENTO EN FALSO | R15: 3223 | RETIRO STAND DE KOF FERIA LOCAL | U15: 3480 | REUBICACION DOMINGO o DIA FESTIVO | X15: 4412 | MOVIMIENTO EN FALSO
M16: 3131 | TRASLADO FORANEO | N16: 3333 | TRASLADO RURAL | P16: 3650 | VISITA IMPRODUCTIVA | R16: 3224 | RETIRO RACK | X16: 4501 | INSTALACION
M17: 3132 | TRASLADO LOCAL | N17: 3346 | PROSPECCION | R17: 3225 | RETIRO CAMION KOF | X17: 4504 | VISITA IMPRODUCTIVA
M18: 3148 | MOVIMIENTO EN FALSO | N18: 3348 | MOVIMIENTO EN FALSO | R18: 3226 | REUBICACION | X18: 4512 | MOVIMIENTO EN FALSO
M19: 3150 | VISITA IMPRODUCTIVA | N19: 3350 | VISITA IMPRODUCTIVA | R19: 3230 | TRASLADO | X19: 4601 | INSTALACION
M20: 3201 | INSTALACION | N20: 3352 | VISITA IMPRODUCTIVA EQUIPO ADICIONAL | R20: 3231 | TRASLADO FORANEO | X20: 4604 | VISITA IMPRODUCTIVA
M21: 3202 | INSTALACION O RETIRO | N21: 3358 | VISITA IMPRODUCTIVA PROSP | R21: 3232 | TRASLADO LOCAL | X21: 4612 | MOVIMIENTO EN FALSO
M22: 3203 | INSTALACION DE ENFRIADOR Y PRODUCTO | R22: 3237 | CAMBIO X RETIRO | X22: 4701 | INSTALACION
M23: 3204 | INSTALACION FORANEO | R23: 3238 | DIA CAMION | X23: 4704 | VISITA IMPRODUCTIVA
M24: 3207 | D2D INSTALACION | R24: 3239 | DIA CAMION D2D | X24: 4712 | MOVIMIENTO EN FALSO
M25: 3209 | INSTALACION O RETIRO EQUIPO ADICIONAL | R25: 3240 | PUNTO DE VENTA FERIA FORANEA | X25: 4812 | MOVIMIENTO EN FALSO
M26: 3211 | INSTALACION RACK | R26: 3241 | PUNTO DE VENTA FERIA LOCAL | X26: 4A01 | INSTALACION
M27: 3212 | INSTALACION CAMION KOF | R27: 3242 | INSTALACION O RETIRO RACK | X27: 4A04 | VISITA IMPRODUCTIVA
M28: 3216 | RETIRO | R28: 3243 | STAND DE KOF FERIA FORANEA | X28: 4A12 | MOVIMIENTO EN FALSO
M29: 3217 | D2D RETIRO | R29: 3244 | STAND DE KOF FERIA LOCAL | X29: 4B12 | MOVIMIENTO EN FALSO
M30: 3218 | RETIRO FORANEO | R30: 3247 | RETIRO SIN COSTO CAMION KOF
M31: 3221 | RETIRO SIN COSTO | R31: 3248 | MOVIMIENTO EN FALSO
M32: 3222 | RETIRO STAND DE KOF FERIA FORANEA | R32: 3249 | REEMPLAZO
M33: 3223 | RETIRO STAND DE KOF FERIA LOCAL | R33: 3250 | VISITA IMPRODUCTIVA
M34: 3224 | RETIRO RACK | R34: 3251 | D2D VISITA IMPRODUCTIVA
M35: 3225 | RETIRO CAMION KOF | R35: 3252 | VISITA IMPRODUCTIVA EQUIPO ADICIONAL
M36: 3226 | REUBICACION | R36: 3253 | VISITA IMPRODUCTIVA FERIA FORANEA
M37: 3230 | TRASLADO | R37: 3254 | VISITA IMPRODUCTIVA FERIA LOCAL
M38: 3231 | TRASLADO FORANEO | R38: 3255 | VISITA IMPRODUCTIVA FORANEO
M39: 3232 | TRASLADO LOCAL | R39: 3259 | VISITA IMPRODUCTIVA RACK
M40: 3237 | CAMBIO X RETIRO | R40: 3260 | V. IMPRODUCTIVA CAMION KOF
...

Sheet ActTypesByServId
A1: ? | ? | B1: 1346 | INSTALACION RB | C1: 1347 | RETIRO RB | D1: 1348 | REUBICACION RB | E1: 1349 | TRASLADO RB | F1: 1350 | VISITA IMPRODUCTIVA RB | G1: 1351 | MOVIMIENTO EN FALSO RB | H1: 3001 | INSTALACION | I1: 3016 | RETIRO | J1: 3021 | RETIRO SIN COSTO | K1: 3030 | TRASLADO | L1: 3050 | VISITA IMPRODUCTIVA | M1: 3101 | INSTALACION | N1: 3116 | RETIRO | O1: 3130 | TRASLADO | P1: 3131 | TRASLADO FORANEO | Q1: 3132 | TRASLADO LOCAL | R1: 3148 | MOVIMIENTO EN FALSO | S1: 3150 | VISITA IMPRODUCTIVA | T1: 3201 | INSTALACION | U1: 3202 | INSTALACION O RETIRO | V1: 3203 | INSTALACION DE ENFRIADOR Y PRODUCTO | W1: 3204 | INSTALACION FORANEO | X1: 3207 | D2D INSTALACION | Y1: 3209 | INSTALACION O RETIRO EQUIPO ADICIONAL | Z1: 3211 | INSTALACION RACK | AA1: 3212 | INSTALACION CAMION KOF | AB1: 3216 | RETIRO | AC1: 3217 | D2D RETIRO | AD1: 3218 | RETIRO FORANEO | AE1: 3221 | RETIRO SIN COSTO | AF1: 3222 | RETIRO STAND DE KOF FERIA FORANEA | AG1: 3223 | RETIRO STAND DE KOF FERIA LOCAL | AH1: 3224 | RETIRO RACK | AI1: 3225 | RETIRO CAMION KOF | AJ1: 3226 | REUBICACION | AK1: 3227 | REUBICACION FORANEO | AL1: 3230 | TRASLADO | AM1: 3231 | TRASLADO FORANEO | AN1: 3232 | TRASLADO LOCAL | AO1: 3236 | CAMBIO X INSTALACION | AP1: 3237 | CAMBIO X RETIRO | AQ1: 3238 | DIA CAMION | AR1: 3239 | DIA CAMION D2D | AS1: 3240 | PUNTO DE VENTA FERIA FORANEA | AT1: 3241 | PUNTO DE VENTA FERIA LOCAL | AU1: 3242 | INSTALACION O RETIRO RACK | AV1: 3243 | STAND DE KOF FERIA FORANEA | AW1: 3244 | STAND DE KOF FERIA LOCAL | AX1: 3245 | SANITIZACION | AY1: 3247 | RETIRO SIN COSTO CAMION KOF | AZ1: 3248 | MOVIMIENTO EN FALSO | BA1: 3249 | REEMPLAZO | BB1: 3250 | VISITA IMPRODUCTIVA | BC1: 3251 | D2D VISITA IMPRODUCTIVA | BD1: 3252 | VISITA IMPRODUCTIVA EQUIPO ADICIONAL | BE1: 3253 | VISITA IMPRODUCTIVA FERIA FORANEA | BF1: 3254 | VISITA IMPRODUCTIVA FERIA LOCAL | BG1: 3255 | VISITA IMPRODUCTIVA FORANEO | BH1: 3257 | VISITA IMPRODUCTIVA - SANITIZACION | BI1: 3259 | VISITA IMPRODUCTIVA RACK | BJ1: 3260 | V. IMPRODUCTIVA CAMION KOF | BK1: 3261 | INSTALACION RB | BL1: 3261 | INSTALACION RED BULL | BM1: 3262 | RETIRO RB | BN1: 3262 | RETIRO RED BULL | BO1: 3263 | REUBICACION RB | BP1: 3264 | TRASLADO RB | BQ1: 3265 | VISITA IMPRODUCTIVA RB | BR1: 3265 | VISITA IMPRODUCTIVA RED BULL | BS1: 3266 | MOVIMIENTO EN FALSO RB | BT1: 3267 | DIA CAMION D2D GEP | BU1: 3268 | RETIRO PUNTO DE VENTA FERIA FORANEA | BV1: 3269 | RETIRO PUNTO DE VENTA FERIA LOCAL | BW1: 3270 | INSTALACION POR REMODELACION CTO FRIO | BX1: 3271 | RETIRO POR REMODELACION CTO FRIO | BY1: 3272 | VISITA IMP POR REMODELACION CTO FRIO | BZ1: 3273 | INSTALACION ESPECIAL | CA1: 3274 | RETIRO ESPECIAL | CB1: 3275 | VISITA IMPRODUCTIVA ESPECIAL | CC1: 3276 | TRABAJO EXTRA ORDINARIO | CD1: 3277 | INSTALACION DOMINGOS Y DIAS FESTIVOS | CE1: 3278 | RETIRO DOMINGOS Y DIAS FESTIVOS | CF1: 3279 | VISIT IMPRODUCT DOMINGOS Y DIAS FESTIVO | CG1: 3301 | INSTALACION | CH1: 3304 | INSTALACION FORANEO | CI1: 3305 | INSTALACION BARRIL MAYOR | CJ1: 3306 | INSTALACION BARRIL MENOR | CK1: 3308 | INSTALACION LOCAL | CL1: 3309 | INSTALACION O RETIRO EQUIPO ADICIONAL | CM1: 3310 | INSTALACION RURAL | CN1: 3316 | RETIRO | CO1: 3318 | RETIRO FORANEO | CP1: 3319 | RETIRO LOCAL | CQ1: 3320 | RETIRO RURAL | CR1: 3326 | REUBICACION | CS1: 3330 | TRASLADO | CT1: 3331 | TRASLADO FORANEO | CU1: 3332 | TRASLADO LOCAL | CV1: 3333 | TRASLADO RURAL | CW1: 3346 | PROSPECCION | CX1: 3348 | MOVIMIENTO EN FALSO | CY1: 3350 | VISITA IMPRODUCTIVA | CZ1: 3352 | VISITA IMPRODUCTIVA EQUIPO ADICIONAL | DA1: 3358 | VISITA IMPRODUCTIVA PROSP | DB1: 3401 | INSTALACION | DC1: 3416 | RETIRO | DD1: 3421 | RETIRO SIN COSTO | DE1: 3426 | REUBICACION | DF1: 3430 | TRASLADO | DG1: 3436 | CAMBIO X INSTALACION | DH1: 3437 | CAMBIO X RETIRO | DI1: 3448 | MOVIMIENTO EN FALSO | DJ1: 3450 | VISITA IMPRODUCTIVA | DK1: 3476 | TRABAJO EXTRA ORDINARIO | DL1: 3477 | INSTALACION DOMINGOS Y DIAS FESTIVOS | DM1: 3478 | RETIRO DOMINGOS Y DIAS FESTIVOS | DN1: 3479 | VISIT IMPRODUCT DOMINGOS Y DIAS FESTIVO | DO1: 3480 | REUBICACION DOMINGO o DIA FESTIVO | DP1: 3501 | INSTALACION | DQ1: 3502 | INSTALACION O RETIRO | DR1: 3504 | INSTALACION FORANEO | DS1: 3516 | RETIRO | DT1: 3518 | RETIRO FORANEO | DU1: 3526 | REUBICACION | DV1: 3527 | REUBICACION FORANEO | DW1: 3530 | TRASLADO | DX1: 3548 | MOVIMIENTO EN FALSO | DY1: 3550 | VISITA IMPRODUCTIVA | DZ1: 3555 | VISITA IMPRODUCTIVA FORANEO | EA1: 3601 | INSTALACION | EB1: 3613 | INSTALACION CABINET | EC1: 3614 | INSTALACION CABINET ZONAS ESPECIALES | ED1: 3616 | RETIRO | EE1: 3621 | RETIRO SIN COSTO | EF1: 3626 | REUBICACION | EG1: 3628 | RETIRO CABINET | EH1: 3629 | RETIRO CABINET ZONAS ESPECIALES | EI1: 3630 | TRASLADO | EJ1: 3631 | TRASLADO FORANEO | EK1: 3632 | TRASLADO LOCAL | EL1: 3634 | FLETE | EM1: 3638 | DIA CAMION | EN1: 3648 | MOVIMIENTO EN FALSO | EO1: 3650 | VISITA IMPRODUCTIVA | EP1: 3701 | INSTALACION | EQ1: 3716 | RETIRO | ER1: 3721 | RETIRO SIN COSTO | ES1: 3726 | REUBICACION | ET1: 3730 | TRASLADO | EU1: 3737 | CAMBIO X RETIRO | EV1: 3748 | MOVIMIENTO EN FALSO | EW1: 3750 | VISITA IMPRODUCTIVA | EX1: 3801 | INSTALACION | EY1: 3816 | RETIRO | EZ1: 3821 | RETIRO SIN COSTO | FA1: 3830 | TRASLADO | FB1: 3848 | MOVIMIENTO EN FALSO | FC1: 3850 | VISITA IMPRODUCTIVA | FD1: 3A01 | INSTALACION | FE1: 3A16 | RETIRO | FF1: 3A30 | TRASLADO | FG1: 3A48 | MOVIMIENTO EN FALSO | FH1: 3A50 | VISITA IMPRODUCTIVA | FI1: 3B01 | INSTALACION | FJ1: 3B07 | D2D INSTALACION | FK1: 3B09 | INSTALACION O RETIRO EQUIPO ADICIONAL | FL1: 3B16 | RETIRO | FM1: 3B17 | D2D RETIRO | FN1: 3B30 | TRASLADO | FO1: 3B39 | DIA CAMION D2D | FP1: 3B48 | MOVIMIENTO EN FALSO | FQ1: 3B50 | VISITA IMPRODUCTIVA | FR1: 3B51 | D2D VISITA IMPRODUCTIVA | FS1: 3B52 | VISITA IMPRODUCTIVA EQUIPO ADICIONAL | FT1: 4112 | MOVIMIENTO EN FALSO | FU1: 4201 | INSTALACION | FV1: 4202 | SANITIZACION | FW1: 4204 | VISITA IMPRODUCTIVA | FX1: 4205 | VISITA IMPRODUCTIVA - SANITIZACION | FY1: 4206 | V. IMPRODUCTIVA CAMION KOF | FZ1: 4210 | INSTALACION CAMION KOF | GA1: 4211 | RETIRO SIN COSTO CAMION KOF | GB1: 4212 | MOVIMIENTO EN FALSO | GC1: 4213 | INSTALACION POR REMODELACION CTO FRIO | GD1: 4214 | VISITA IMP POR REMODELACION CTO FRIO | GE1: 4215 | INSTALACION DOMINGOS Y DIAS FESTIVOS | GF1: 4216 | VISIT IMPRODUCT DOMINGOS Y DIAS FESTIVO | GG1: 4412 | MOVIMIENTO EN FALSO | GH1: 4501 | INSTALACION | GI1: 4504 | VISITA IMPRODUCTIVA | GJ1: 4512 | MOVIMIENTO EN FALSO | GK1: 4601 | INSTALACION | GL1: 4604 | VISITA IMPRODUCTIVA | GM1: 4612 | MOVIMIENTO EN FALSO | GN1: 4701 | INSTALACION | GO1: 4704 | VISITA IMPRODUCTIVA | GP1: 4712 | MOVIMIENTO EN FALSO | GQ1: 4812 | MOVIMIENTO EN FALSO | GR1: 4A01 | INSTALACION | GS1: 4A04 | VISITA IMPRODUCTIVA | GT1: 4A12 | MOVIMIENTO EN FALSO | GU1: 4B12 | MOVIMIENTO EN FALSO
A2: ? | ? | B2: 2001 | INSTALACION | C2: 2002 | MOVIMIENTO | D2: 2007 | MOVIMIENTO | E2: 2006 | MOVIMIENTO | F2: 2003 | VISITA IMPRODUCTIVA | G2: 2014 | RETIRO NO REALIZADO | H2: 2001 | INSTALACION | I2: 2002 | MOVIMIENTO | J2: 2002 | MOVIMIENTO | K2: 2006 | MOVIMIENTO | L2: 2003 | VISITA IMPRODUCTIVA | M2: 2001 | INSTALACION | N2: 2002 | MOVIMIENTO | O2: 2006 | MOVIMIENTO | P2: 2006 | MOVIMIENTO | Q2: 2006 | MOVIMIENTO | R2: 2014 | RETIRO NO REALIZADO | S2: 2003 | VISITA IMPRODUCTIVA | T2: 2001 | INSTALACION | U2: 2001 | INSTALACION | V2: 2001 | INSTALACION | W2: 2001 | INSTALACION | X2: 2001 | INSTALACION | Y2: 2001 | INSTALACION | Z2: 2001 | INSTALACION | AA2: 2001 | INSTALACION | AB2: 2002 | MOVIMIENTO | AC2: 2002 | MOVIMIENTO | AD2: 2002 | MOVIMIENTO | AE2: 2002 | MOVIMIENTO | AF2: 2002 | MOVIMIENTO | AG2: 2002 | MOVIMIENTO | AH2: 2002 | MOVIMIENTO | AI2: 2002 | MOVIMIENTO | AJ2: 2007 | MOVIMIENTO | AK2: 2007 | MOVIMIENTO | AL2: 2006 | MOVIMIENTO | AM2: 2006 | MOVIMIENTO | AN2: 2006 | MOVIMIENTO | AO2: 2009 | INSTALACION / RETIRO EQUIPO | AP2: 2002 | MOVIMIENTO | AQ2: 2001 | INSTALACION | AR2: 2001 | INSTALACION | AS2: 2001 | INSTALACION | AT2: 2001 | INSTALACION | AU2: 2001 | INSTALACION | AV2: 2001 | INSTALACION | AW2: 2001 | INSTALACION | AX2: 2004 | SANITIZACION | AY2: 2002 | MOVIMIENTO | AZ2: 2014 | RETIRO NO REALIZADO | BA2: 2016 | REEMPLAZO DE EQUIPO | BB2: 2003 | VISITA IMPRODUCTIVA | BC2: 2003 | VISITA IMPRODUCTIVA | BD2: 2003 | VISITA IMPRODUCTIVA | BE2: 2003 | VISITA IMPRODUCTIVA | BF2: 2003 | VISITA IMPRODUCTIVA | BG2: 2003 | VISITA IMPRODUCTIVA | BH2: 2008 | VISITA A PUNTO DE VENTA | BI2: 2003 | VISITA IMPRODUCTIVA | BJ2: 2003 | VISITA IMPRODUCTIVA | BK2: 2001 | INSTALACION | BL2: 2001 | INSTALACION | BM2: 2002 | MOVIMIENTO | BN2: 2002 | MOVIMIENTO | BO2: 2007 | MOVIMIENTO | BP2: 2006 | MOVIMIENTO | BQ2: 2003 | VISITA IMPRODUCTIVA | BR2: 2003 | VISITA IMPRODUCTIVA | BS2: 2014 | RETIRO NO REALIZADO | BT2: 2001 | INSTALACION | BU2: 2002 | MOVIMIENTO | BV2: 2002 | MOVIMIENTO | BW2: 2018 | INSTALACION POR REMODELACION | BX2: 2019 | RETIRO POR REMODELACION | BY2: 2003 | VISITA IMPRODUCTIVA | BZ2: 2020 | INSTALACION ESPECIAL | CA2: 2021 | RETIRO ESPECIAL | CB2: 2022 | VISITA IMPRODUCTIVA ESPECIAL | CC2: 2023 | TRABAJO EXTRA ORDINARIO | CD2: 2001 | INSTALACION | CE2: 2002 | MOVIMIENTO | CF2: 2003 | VISITA IMPRODUCTIVA | CG2: 2001 | INSTALACION | CH2: 2001 | INSTALACION | CI2: 2001 | INSTALACION | CJ2: 2001 | INSTALACION | CK2: 2001 | INSTALACION | CL2: 2001 | INSTALACION | CM2: 2001 | INSTALACION | CN2: 2002 | MOVIMIENTO | CO2: 2002 | MOVIMIENTO | CP2: 2002 | MOVIMIENTO | CQ2: 2002 | MOVIMIENTO | CR2: 2007 | MOVIMIENTO | CS2: 2006 | MOVIMIENTO | CT2: 2006 | MOVIMIENTO | CU2: 2006 | MOVIMIENTO | CV2: 2006 | MOVIMIENTO | CW2: 2011 | PROSPECCION | CX2: 2014 | RETIRO NO REALIZADO | CY2: 2003 | VISITA IMPRODUCTIVA | CZ2: 2003 | VISITA IMPRODUCTIVA | DA2: 2012 | VISITA IMPRODUCTIVA PROSP | DB2: 2001 | INSTALACION | DC2: 2002 | MOVIMIENTO | DD2: 2002 | MOVIMIENTO | DE2: 2007 | MOVIMIENTO | DF2: 2006 | MOVIMIENTO | DG2: 2001 | INSTALACION | DH2: 2002 | MOVIMIENTO | DI2: 2014 | RETIRO NO REALIZADO | DJ2: 2003 | VISITA IMPRODUCTIVA | DK2: 2023 | TRABAJO EXTRA ORDINARIO | DL2: 2001 | INSTALACION | DM2: 2002 | MOVIMIENTO | DN2: 2003 | VISITA IMPRODUCTIVA | DO2: 2007 | MOVIMIENTO | DP2: 2001 | INSTALACION | DQ2: 2001 | INSTALACION | DR2: 2001 | INSTALACION | DS2: 2002 | MOVIMIENTO | DT2: 2002 | MOVIMIENTO | DU2: 2007 | MOVIMIENTO | DV2: 2007 | MOVIMIENTO | DW2: 2006 | MOVIMIENTO | DX2: 2014 | RETIRO NO REALIZADO | DY2: 2003 | VISITA IMPRODUCTIVA | DZ2: 2003 | VISITA IMPRODUCTIVA | EA2: 2001 | INSTALACION | EB2: 2001 | INSTALACION | EC2: 2001 | INSTALACION | ED2: 2002 | MOVIMIENTO | EE2: 2002 | MOVIMIENTO | EF2: 2007 | MOVIMIENTO | EG2: 2002 | MOVIMIENTO | EH2: 2002 | MOVIMIENTO | EI2: 2006 | MOVIMIENTO | EJ2: 2006 | MOVIMIENTO | EK2: 2006 | MOVIMIENTO | EL2: 2006 | MOVIMIENTO | EM2: 2001 | INSTALACION | EN2: 2014 | RETIRO NO REALIZADO | EO2: 2003 | VISITA IMPRODUCTIVA | EP2: 2001 | INSTALACION | EQ2: 2002 | MOVIMIENTO | ER2: 2002 | MOVIMIENTO | ES2: 2007 | MOVIMIENTO | ET2: 2006 | MOVIMIENTO | EU2: 2008 | MOVIMIENTO | EV2: 2014 | RETIRO NO REALIZADO | EW2: 2003 | VISITA IMPRODUCTIVA | EX2: 2001 | INSTALACION | EY2: 2002 | MOVIMIENTO | EZ2: 2002 | MOVIMIENTO | FA2: 2006 | MOVIMIENTO | FB2: 2014 | RETIRO NO REALIZADO | FC2: 2003 | VISITA IMPRODUCTIVA | FD2: 2001 | INSTALACION | FE2: 2002 | MOVIMIENTO | FF2: 2006 | MOVIMIENTO | FG2: 2014 | RETIRO NO REALIZADO | FH2: 2003 | VISITA IMPRODUCTIVA | FI2: 2001 | INSTALACION | FJ2: 2001 | INSTALACION | FK2: 2001 | INSTALACION | FL2: 2002 | MOVIMIENTO | FM2: 2002 | MOVIMIENTO | FN2: 2006 | MOVIMIENTO | FO2: 2001 | INSTALACION | FP2: 2014 | RETIRO NO REALIZADO | FQ2: 2003 | VISITA IMPRODUCTIVA | FR2: 2003 | VISITA IMPRODUCTIVA | FS2: 2003 | VISITA IMPRODUCTIVA | FT2: 2015 | INSTALACION NO REALIZADA | FU2: 2001 | INSTALACION | FV2: 2004 | SANITIZACION | FW2: 2010 | VISITA IMPRODUCTIVA | FX2: 2013 | VISITA A PUNTO DE VENTA | FY2: 2010 | VISITA IMPRODUCTIVA | FZ2: 2001 | INSTALACION | GA2: 2002 | MOVIMIENTO | GB2: 2015 | INSTALACION NO REALIZADA | GC2: 2018 | INSTALACION POR REMODELACION | GD2: 2010 | VISITA IMPRODUCTIVA | GE2: 2001 | INSTALACION | GF2: 2010 | VISITA IMPRODUCTIVA | GG2: 2015 | INSTALACION NO REALIZADA | GH2: 2001 | INSTALACION | GI2: 2010 | VISITA IMPRODUCTIVA | GJ2: 2015 | INSTALACION NO REALIZADA | GK2: 2001 | INSTALACION | GL2: 2010 | VISITA IMPRODUCTIVA | GM2: 2015 | INSTALACION NO REALIZADA | GN2: 2001 | INSTALACION | GO2: 2010 | VISITA IMPRODUCTIVA | GP2: 2015 | INSTALACION NO REALIZADA | GQ2: 2015 | INSTALACION NO REALIZADA | GR2: 2001 | INSTALACION | GS2: 2010 | VISITA IMPRODUCTIVA | GT2: 2015 | INSTALACION NO REALIZADA | GU2: 2015 | INSTALACION NO REALIZADA
G3: 2015 | INSTALACION NO REALIZADA | R3: 2015 | INSTALACION NO REALIZADA | S3: 2017 | VISITA IMPRODUCTIVA RET | U3: 2005 | MOVIMIENTO | Y3: 2005 | MOVIMIENTO | AS3: 2002 | MOVIMIENTO | AT3: 2002 | MOVIMIENTO | AU3: 2005 | MOVIMIENTO | AZ3: 2015 | INSTALACION NO REALIZADA | BB3: 2017 | VISITA IMPRODUCTIVA RET | BC3: 2017 | VISITA IMPRODUCTIVA RET | BE3: 2017 | VISITA IMPRODUCTIVA RET | BF3: 2017 | VISITA IMPRODUCTIVA RET | BG3: 2017 | VISITA IMPRODUCTIVA RET | BJ3: 2017 | VISITA IMPRODUCTIVA RET | BQ3: 2017 | VISITA IMPRODUCTIVA RET | BR3: 2017 | VISITA IMPRODUCTIVA RET | BS3: 2015 | INSTALACION NO REALIZADA | BZ3: 2021 | INSTALACION ESPECIAL | CL3: 2005 | MOVIMIENTO | CX3: 2015 | INSTALACION NO REALIZADA | CY3: 2017 | VISITA IMPRODUCTIVA RET | DI3: 2015 | INSTALACION NO REALIZADA | DJ3: 2017 | VISITA IMPRODUCTIVA RET | DQ3: 2005 | MOVIMIENTO | DX3: 2015 | INSTALACION NO REALIZADA | DY3: 2017 | VISITA IMPRODUCTIVA RET | DZ3: 2017 | VISITA IMPRODUCTIVA RET | EN3: 2015 | INSTALACION NO REALIZADA | EO3: 2017 | VISITA IMPRODUCTIVA RET | EV3: 2015 | INSTALACION NO REALIZADA | EW3: 2017 | VISITA IMPRODUCTIVA RET | FB3: 2015 | INSTALACION NO REALIZADA | FC3: 2017 | VISITA IMPRODUCTIVA RET | FG3: 2015 | INSTALACION NO REALIZADA | FH3: 2017 | VISITA IMPRODUCTIVA RET | FK3: 2005 | MOVIMIENTO | FP3: 2015 | INSTALACION NO REALIZADA | FQ3: 2017 | VISITA IMPRODUCTIVA RET | FR3: 2017 | VISITA IMPRODUCTIVA RET

Sheet ActIdsByActTypes
A1: ? | ? | B1: 2001 | INSTALACION | C1: 2002 | MOVIMIENTO | D1: 2003 | VISITA IMPRODUCTIVA | E1: 2004 | SANITIZACION | F1: 2005 | MOVIMIENTO | G1: 2006 | MOVIMIENTO | H1: 2007 | MOVIMIENTO | I1: 2008 | MOVIMIENTO | J1: 2008 | VISITA A PUNTO DE VENTA | K1: 2009 | INSTALACION / RETIRO EQUIPO | L1: 2010 | VISITA IMPRODUCTIVA | M1: 2011 | PROSPECCION | N1: 2012 | VISITA IMPRODUCTIVA PROSP | O1: 2013 | VISITA A PUNTO DE VENTA | P1: 2014 | RETIRO NO REALIZADO | Q1: 2015 | INSTALACION NO REALIZADA | R1: 2016 | REEMPLAZO DE EQUIPO | S1: 2017 | VISITA IMPRODUCTIVA RET | T1: 2018 | INSTALACION POR REMODELACION | U1: 2019 | RETIRO POR REMODELACION | V1: 2020 | INSTALACION ESPECIAL | W1: 2021 | INSTALACION ESPECIAL | X1: 2021 | RETIRO ESPECIAL | Y1: 2022 | VISITA IMPRODUCTIVA ESPECIAL | Z1: 2023 | TRABAJO EXTRA ORDINARIO
A2: ? | ? | B2: 3001 | INSTALACION DE EQUIPO | C2: 3002 | RETIRO DE EQUIPO | D2: 3004 | VISITA A PUNTO DE VENTA | E2: 3008 | LIMPIEZA | F2: 3002 | RETIRO DE EQUIPO | G2: 3003 | TRASLADO DE EQUIPO | H2: 3005 | REUBICACION DE EQUIPO | I2: 3004 | VISITA A PUNTO DE VENTA | J2: 3004 | VISITA A PUNTO DE VENTA | K2: 3001 | INSTALACION DE EQUIPO | L2: 3004 | VISITA A PUNTO DE VENTA | M2: 3010 | DIAGNOSTICO | N2: 3004 | VISITA A PUNTO DE VENTA | O2: 3004 | VISITA A PUNTO DE VENTA | P2: 3002 | RETIRO DE EQUIPO | Q2: 3001 | INSTALACION DE EQUIPO | R2: 3002 | RETIRO DE EQUIPO | S2: 3004 | VISITA A PUNTO DE VENTA | T2: 3011 | INSTALACION POR REMODELACION | U2: 3012 | RETIRO POR REMODELACION | V2: 3001 | INSTALACION DE EQUIPO | W2: 3002 | RETIRO DE EQUIPO | X2: 3002 | RETIRO DE EQUIPO | Y2: 3004 | VISITA A PUNTO DE VENTA | Z2: 3014 | RENTA DE CAMIONETA
B3: 3008 | INSTALACION DE EQUIPO NVO | C3: 3012 | RETIRO POR REMODELACION | D3: 3004 | VISITA A PUNTO DE VENTA INST | T3: 3013 | INSTALACION NVO POR REMODELACION | Z3: 3015 | TRABAJO ESPECIAL
D4: 3006 | VISITA A PUNTO DE VENTA RET

Sheet Categories
A1: Code | B1: Description | C1: Catalog | D1: 13 | E1: 20 | F1: 16 | G1: 17 | H1: 18 | I1: 12 | J1: 19 | K1: 11 | L1: 14 | M1: 0B | N1: 15 | O1: 1A | P1: 1E | Q1: 1B | R1: 1C | S1: 1D | T1: 1F | U1: 1G | V1: 1H | W1: 1I
A2: 13 | B2: BARRIL | C2: 13 | BARRIL
A3: 20 | B3: CAFETERAS | C3: 20 | CAFETERAS
A4: 16 | B4: CONGELADOR | C4: 16 | CONGELADOR
A5: 17 | B5: CORTINA DE AIRE | C5: 17 | CORTINA DE AIRE
A6: 18 | B6: DISPAGUA | C6: 18 | DISPAGUA
A7: 12 | B7: ENFRIADOR | C7: 12 | ENFRIADOR
A8: 19 | B8: HIELERA | C8: 19 | HIELERA
A9: 11 | B9: MAQHIELO | C9: 11 | MAQHIELO
A10: 14 | B10: MAQVENDING | C10: 14 | MAQVENDING
A11: 0B | B11: UNID REFRI VENDING | C11: 0B | UNID REFRI VENDING
A12: 15 | B12: VITRINA | C12: 15 | VITRINA
A13: 1A | B13: MESA FRIA | C13: 1A | MESA FRIA
... A21: 1I | B21: SIM | C21: 1I | SIM
